Workbook

Sheet MATERIAL
A1: codigo | B1: Texto breve de material (REVISADA) | C1: Unidade de medida básica | D1: CODIGO SAP | E1: Peso bruto | F1: Unidade de peso | G1: Código ABC
A2: 90399 | B2: ESTRIBO P/ BRACO TIPO L ACO GALV 140X70X50MM 400DAN | C2: PC
A3: 90648 | B3: AFASTADOR ISOLADOR PILAR ACO GALV 100X320MM 10MM 320DAN | C3: PC | D3: 10016721 | E3: 1 | F3: KG | G3: C
A4: 90301 | B4: ALCA PREF CORD ACO-ZN 6,40MM 5X2.18MM 460MM AMR | C4: PÇ
A5: 90301 | B5: ALCA PREF CORD ACO-ZN 6,40MM 5X2.18MM 460MM AMR | C5: UN
A6: 90013 | B6: ALCA PREF CORD ACO-ZN 9,50MM 6X2.54MM 965MM LRJ | C6: PÇ | D6: 10000856 | E6: 0.245 | F6: KG | G6: C
A7: 90013 | B7: ALCA PREF CORD ACO-ZN 9,50MM 6X2.54MM 965MM LRJ | C7: UN | D7: CODIGO PADRÃO | E7: 4.02 | F7: KG | G7: C
A8: 113 | B8: ALCA PREF DIS CA/CAA 2/0AWG 10,4-11,69MM | C8: PC | D8: 10000857 | E8: 0.39 | F8: KG | G8: C
A9: 2814 | B9: ALCA PREF DIS CA/CAA 6AWG 4,62-5,15MM | C9: PC
A10: 90315 | B10: ALCA PREF DISTR ACO-ALUM 9,27-10,40MM 660MM AMR | C10: PC | D10: 10000846 | E10: 0.34 | F10: KG | G10: C
A11: 90315 | B11: ALCA PREF DISTR ACO-ALUM 9,27-10,40MM 660MM AMR | C11: UN | D11: 10000805 | E11: 0.895 | F11: KG | G11: C
A12: 90308 | B12: ALCA PREF DISTR ACO-ZINC 13,10-14,65MM 865MM VRM | C12: PC | D12: 10000800 | E12: 0.24 | F12: KG | G12: C
A13: 90308 | B13: ALCA PREF DISTR ACO-ZINC 13,10-14,65MM 865MM VRM 4/0 | C13: UN | D13: 10000809 | E13: 0.18 | F13: KG | G13: C
A14: 90309 | B14: ALCA PREF DISTR ACO-ZINC 16,20-18,15MM 980MM VRD | C14: UN | D14: 10000817 | E14: 0.6 | F14: KG | G14: C
A15: 90307 | B15: ALCA PREF DISTR ACO-ZINC 9,15-10,25MM 670MM AMR | C15: UN | D15: 10000849 | E15: 0.25 | F15: KG
A16: 121 | B16: ALCA PREF ESTAI 6,4MM HS/SM | D16: 10000840 | E16: 0.21 | F16: KG
A17: 121 | B17: ALCA PREF ESTAI 6,4MM HS/SM | C17: PC | D17: 10000808 | E17: 0.11 | F17: KG | G17: C
A18: 90303 | B18: ALCA PREF SERV ACO-ZINC 3,90-4,30MM 345MM MRM | C18: UN
A19: 90305 | B19: ALCA PREF SERV ACO-ZINC 6,00-6,70MM 330MM LRJ | C19: UN | D19: 10000807 | E19: 0.7 | F19: KG | G19: C
A20: 90305 | B20: ALCA PREF SERV ACO-ZINC 6,00-6,70MM 330MM LRJ | C20: UN | D20: 10000812 | E20: 0.032 | F20: KG
A21: 2815 | B21: ALCA PREFORMADA DISTRIBUICAO 2AWG 610,0MM | C21: PC | D21: 10000816 | E21: 0.31 | F21: KG
A22: 2815 | B22: ALCA PREFORMADA DISTRIBUICAO 2AWG 610,0MM | C22: PC | D22: 10000859 | E22: 0.4 | F22: KG | G22: C
A23: 2878 | B23: ALCA PREFORMADA SERVICO 8AWG 355,0MM | C23: PC | D23: 10000853 | E23: 0.18 | F23: KG | G23: C
A24: 2878 | B24: ALCA PREFORMADA SERVICO 8AWG 355,0MM | C24: PC | D24: 10000839 | E24: 0.46 | F24: KG | G24: C
A25: 90537 | B25: ANEL AMAR ELASTOMERICO P/ESPACADOR 45X90X140MM CNZ | C25: UN | D25: 10000867 | E25: 0.02 | F25: KG | G25: C
A26: 90538 | B26: ANEL AMAR ELASTOMERICO P/ISOLADOR 15,0KV 45X110X160MM VRM | C26: UN | D26: 10000868 | E26: 0.01 | F26: KG
A27: 90538 | B27: ANEL AMAR ELASTOMERICO P/ISOLADOR 15,0KV 45X110X160MM VRM | C27: UN
A28: 90538 | B28: ANEL AMARR ELASTOMERICO P/ISOLADOR 15,0KV 45X110X160MM VRM | C28: UN | D28: 10002607 | E28: 0.8 | F28: KG | G28: C
A29: 90300 | B29: ARAME REDOND ACO-GALV DURA 2,77MM BWG12 | C29: UN | D29: 10002607 | E29: 0.8 | F29: KG | G29: C
A30: 90300 | B30: ARAME REDOND ACO-GALV DURA 2,77MM BWG12 | C30: KG | D30: 10002608 | E30: 1.92 | F30: KG | G30: C
A31: 2966 | B31: ARMACAO SECUNDARIA ACO CARB 2 ESTRIBOS 5,0X 325,0X 310,0MM | C31: PÇ
A32: 2966 | B32: ARMACAO SECUNDARIA ACO CARB 2 ESTRIBOS 5,0X 325,0X 310,0MM | C32: PC | D32: 10002609 | E32: 3.06 | F32: KG
A33: 90393 | B33: ARMACAO SECUNDARIA ACO GALV 1 ESTRIBO 110X50X5,0MM 125X16MM | C33: PC | D33: 10002610 | E33: 4.055 | F33: KG | G33: C
A34: 90393 | B34: ARMACAO SECUNDARIA ACO GALV 1 ESTRIBO 110X50X5,0MM 125X16MM | C34: UN | D34: 10008218 | E34: 0.02 | F34: KG
A35: 92017 | B35: ARMACAO SECUNDARIA ACO GALV 2 ESTRIBO 310X50X5,0MM 325X16MM | C35: PC | D35: 10000872 | E35: 0.026 | F35: KG | G35: C
A36: 90893 | B36: ARRUELA ESPACADORA FERRO FUND 50X18X30MM | C36: PC | D36: 10000875 | E36: 0.55 | F36: KG | G36: C
A37: 3055 | B37: ARRUELA ESPACADORA LISA CIRCULAR FOFO GALV DIN9021 M18 | C37: PÇ | D37: 10000878 | E37: 0.5 | F37: KG | G37: C
A38: 90893 | B38: ARRUELA ESPACADORA LISA CIRCULAR FOFO GALV DIN9021 M18 | C38: PC | D38: 10000955 | E38: 9.2 | F38: KG | G38: C
A39: 90389 | B39: ARRUELA QUADRADA ACO GALV 38X18X3MM | C39: UN | D39: 10000995 | E39: 4.54 | F39: KG | G39: C
A40: 90389 | B40: ARRUELA QUADRADA ACO GALV 38X18X3MM | C40: UN
...

Sheet RELAÇAO DE MATERIAL
A1: cod_material | B1: descricao | C1: und_medida | D1: val_material | E1: situacao | F1: qtd_item_prev | G1: qtd_rma | H1: qtd_outros | I1: qtd_dma | J1: qtdmat_apl | K1: qtdmat_apl_fsc
A2: 90399 | B2: ESTRIBO P/ BRACO TIPO L ACO GALV 140X70X50MM 400DAN | C2: UN | D2: 12 | E2: NORMAL | F2: 2 | G2: 2 | H2: 0 | I2: 0 | K2: 2
A3: 90013 | B3: ALCA PREF CORD ACO-ZN 9,50MM 6X2.54MM 965MM LRJ | C3: UN | D3: 6.76 | E3: NORMAL | F3: 10 | G3: 6 | H3: 0 | I3: 0 | K3: 4
A4: 90315 | B4: ALCA PREF DISTR ACO-ALUM 9,27-10,40MM 660MM AMR | C4: UN | D4: 4.35 | E4: NORMAL | F4: 32 | G4: 14 | H4: 0 | I4: 0 | K4: 0
A5: 90308 | B5: ALCA PREF DISTR ACO-ZINC 13,10-14,65MM 865MM VRM | C5: UN | D5: 8.08 | E5: NORMAL | F5: 48 | G5: 36 | H5: 0 | I5: 0 | K5: 0
A6: 121 | B6: ALCA PREF ESTAI 6,4MM HS/SM | C6: PC | D6: 3.03 | E6: NORMAL | F6: 26 | G6: 13 | H6: 0 | I6: 0 | K6: 0
A7: 90305 | B7: ALCA PREF SERV ACO-ZINC 6,00-6,70MM 330MM LRJ | C7: UN | D7: 1.05 | E7: NORMAL | F7: 5 | G7: 0 | H7: 0 | I7: 0 | K7: 0
A8: 2815 | B8: ALCA PREFORMADA DISTRIBUICAO 2AWG 610,0MM | C8: PC | D8: 3.53 | E8: NORMAL | F8: 97 | G8: 19 | H8: 0 | I8: 0 | K8: 0
A9: 2878 | B9: ALCA PREFORMADA SERVICO 8AWG 355,0MM | C9: PC | D9: 0.58 | E9: NORMAL | F9: 0 | G9: 2 | H9: 0 | I9: 0 | K9: 0
A10: 90538 | B10: ANEL AMAR ELASTOMERICO P/ISOLADOR 15,0KV 45X110X160MM VRM | C10: UN | D10: 2.26 | E10: NORMAL | F10: 9 | G10: 3 | H10: 0 | I10: 0 | K10: 0
A11: 90300 | B11: ARAME REDOND ACO-GALV DURA 2,77MM BWG12 | C11: KG | D11: 21.32 | E11: NORMAL | F11: 1 | G11: 0 | H11: 0 | I11: 0 | K11: 0
A12: 2966 | B12: ARMACAO SECUNDARIA ACO CARB 2 ESTRIBOS 5,0X 325,0X 310,0MM | C12: PC | D12: 14.92 | E12: NORMAL | F12: 18 | G12: 4 | H12: 0 | I12: 0 | K12: 0
A13: 90393 | B13: ARMACAO SECUNDARIA ACO GALV 1 ESTRIBO 110X50X5,0MM 125X16MM | C13: UN | D13: 7.87 | E13: NORMAL | F13: 8 | G13: 1 | H13: 0 | I13: 0 | K13: 0
A14: 90893 | B14: ARRUELA ESPACADORA LISA CIRCULAR FOFO GALV DIN9021 M18 | C14: PC | D14: 14.5 | E14: DESPADRONIZADO | F14: 11 | G14: 8 | H14: 0 | I14: 0 | K14: 8
A15: 90389 | B15: ARRUELA QUADRADA ACO GALV 38X18X3MM | C15: UN | D15: 0.36 | E15: NORMAL | F15: 224 | G15: 70 | H15: 0 | I15: 0 | J15: 0 | K15: 2
A16: 90540 | B16: BRACO ANTI-BALANCO PEAD 15,0KV 305MM | C16: UN | D16: 12.7 | E16: NORMAL | F16: 2 | G16: 2 | H16: 0 | I16: 0 | K16: 2
A17: 90542 | B17: BRACO REDE COMP TIPO C 15KV SAE1010/20 580MM | C17: UN | D17: 52.56 | E17: NORMAL | F17: 3 | G17: 1 | H17: 0 | I17: 0 | K17: 0
A18: 90544 | B18: BRACO REDE COMP TIPO L 15KV SAE1010/20 354MM | C18: UN | D18: 44.78 | E18: NORMAL | F18: 2 | G18: 2 | H18: 0 | I18: 0 | K18: 2
A19: 90274 | B19: CABO ALUM MULTIPLEX 0,6/1KV XLPE 2F 10MM2+10MM2 | C19: M | D19: 3.8065 | E19: NORMAL | F19: 0 | G19: 5 | H19: 0 | I19: 0 | K19: 0
A20: 90290 | B20: CABO ALUM MULTIPLEX 0,6/1KV XLPE 3F 120MM2+70MM2 | C20: M | D20: 43.24 | E20: NORMAL | F20: 960 | G20: 180 | H20: 0 | I20: 0 | K20: 0
A21: 90288 | B21: CABO ALUM MULTIPLEX 0,6/1KV XLPE 3F 35MM2+35MM2 | C21: M | D21: 12.06 | E21: NORMAL | F21: 60.3 | G21: 60 | H21: 0 | I21: 0 | K21: 0
A22: 90289 | B22: CABO ALUM MULTIPLEX 0,6/1KV XLPE 3F 70MM2+70MM2 | C22: M | D22: 17.26 | E22: NORMAL | F22: 80 | G22: 0 | H22: 0 | I22: 0 | J22: 0 | K22: 0
A23: 90259 | B23: CABO ALUM NU 1F CA/AAC 1/0AWG POPPY | C23: KG | D23: 14.33 | E23: NORMAL | F23: 331.56 | G23: 0 | H23: 0 | I23: 0 | J23: 0 | K23: 0
A24: 90258 | B24: CABO ALUM NU 1F CA/AAC 2AWG IRIS | C24: KG | D24: 43.48 | E24: NORMAL | F24: 317.47 | G24: 74 | H24: 0 | I24: 0 | J24: 0 | K24: 0
A25: 690327 | B25: CABO ALUM NU 1F CA/AAC 336,4MCM TULIP | C25: KG | D25: 36.5054 | E25: NORMAL | F25: 1935 | G25: 0 | H25: 0 | I25: 1935 | J25: 0 | K25: 0
A26: 90263 | B26: CABO ALUM NU CAA 1/0AWG 1F RAVEN | C26: KG | D26: 36.04 | E26: NORMAL | F26: 0.65 | G26: 0.65 | H26: 0 | I26: 0 | K26: 0.65
A27: 90262 | B27: CABO ALUM NU CAA 2AWG 1F SPARROW | C27: KG | D27: 25.97 | E27: NORMAL | F27: 225.76 | G27: 0 | H27: 0 | I27: 0 | K27: 0
A28: 90560 | B28: CABO ALUM NU CAA 4AWG 1F SWAN | C28: KG | D28: 14.64 | E28: NORMAL | F28: 108.36 | G28: 0 | H28: 0 | I28: 0 | J28: 0 | K28: 0
A29: 90267 | B29: CABO ALUM PROT SPL 120MM2 15,0KV 1F 15 FIOS | C29: M | D29: 14.52 | E29: NORMAL | F29: 60 | G29: 0 | H29: 0 | I29: 0 | J29: 0 | K29: 0
A30: 90266 | B30: CABO ALUM PROT SPL 120MM2 15,0KV 1F 15 FIOS | C30: M | D30: 14.52
A31: 90268 | B31: CABO ALUM PROT SPL 15,0KV 185MM2 1F 30 FIOS | C31: M | D31: 21.09 | E31: NORMAL | F31: 705 | G31: 505 | H31: 0 | I31: 30 | K31: 355
A32: 91462 | B32: CABO COBRE ISOLAD 450/750V BWF/PVC 120MM2 CL2/4/5 PRT | C32: M | D32: 87.4 | E32: NORMAL | F32: 66 | G32: 24 | H32: 0 | I32: 0 | K32: 0
A33: 623984 | B33: CABO CONTROLE 1KV COBRE PVC 2X2,5MM2 CL2 | C33: M | D33: 5.58 | E33: NORMAL | F33: 10 | G33: 0 | H33: 0 | I33: 0 | K33: 0
A34: 3098 | B34: CABO ISOL 750V COBRE PVC/BWF 10MM2 1F CL2 PT | C34: M | D34: 7.64 | E34: NORMAL | F34: 64 | G34: 20 | H34: 0 | I34: 10 | J34: 0 | K34: 0
A35: 90294 | B35: CABO PROT SPL COBRE 16MM2 15,0KV 1F 6 FIOS | C35: M | D35: 16.67 | E35: NORMAL | F35: 143 | G35: 30 | H35: 0 | I35: 4 | J35: 0 | K35: 0
A36: 4475 | B36: CAPA ISOL CONECTOR CUNHA 15KV PE | C36: PC | D36: 5 | E36: DESPADRONIZADO | F36: 6 | G36: 3 | H36: 0 | I36: 0 | K36: 0
A37: 90968 | B37: CAPA PROT PEAD TRANSF BT 1,2 KV 247X85X70MM 2X24MM | C37: UN | D37: 24.42 | E37: NORMAL | F37: 69 | G37: 24 | H37: 0 | I37: 0 | K37: 0
A38: 90586 | B38: CAPA PROT PEAD TRANSF MT 15/36,2KV 135X110MM | C38: UN | D38: 7.54 | E38: NORMAL | F38: 64 | G38: 38 | H38: 0 | I38: 12 | J38: 0 | K38: 0
A39: 90486 | B39: CARTUCHO FERRAM CONECTOR CUNHA AMARELO 24,30MM | C39: UN | D39: 0.7 | E39: NORMAL | F39: 1 | G39: 0 | H39: 0 | I39: 0 | K39: 0
A40: 90487 | B40: CARTUCHO FERRAM CONECTOR CUNHA AZUL 14,80MM | C40: UN | D40: 0.47 | E40: NORMAL | F40: 455 | G40: 210 | H40: 0 | I40: 30 | J40: 0 | K40: 33
...

Sheet Página8

Sheet CONTRATO 2024014901
A1: cod_grupo | B1: descricao | C1: cod_mobra | D1: descricao | E1: instalar | F1: retirar | G1: instalar_emergencial | H1: retirar_emergencial
A2: 500 | B2: SAP | C2: 92525 | D2: SERV. EMERG. HORARIO COMERCIAL - ADICIONAL 12% | E2: 1 | F2: 0 | G2: 0 | H2: 0
A3: 500 | B3: SAP | C3: 6046 | D3: DESAT CHAVE FUSIVEL 3 OP < 34,5 KV | E3: 0 | F3: 38.28 | G3: 0 | H3: 0
A4: 500 | B4: SAP | C4: 6071 | D4: INST CHAVE FUSIVEL < 34,5 KV LM | E4: 95.72 | F4: 0 | G4: 0 | H4: 0
A5: 500 | B5: SAP | C5: 6073 | D5: INST CHAVE FUSIVEL 3 OP < 34,5 KV | E5: 124.44 | F5: 0 | G5: 0 | H5: 0
A6: 500 | B6: SAP | C6: 6074 | D6: INST CHAVE FUSIVEL 3 OP => 34,5 KV | E6: 124.44 | F6: 0 | G6: 0 | H6: 0
A7: 500 | B7: SAP | C7: 6083 | D7: INST PARA-RAIOS RD => 34,5 KV LM | E7: 95.72 | F7: 0 | G7: 0 | H7: 0
A8: 500 | B8: SAP | C8: 6137 | D8: LIMP FAIXA SERVIDAO MECANIZADA | E8: 2758.72 | F8: 0 | G8: 0 | H8: 0
A9: 500 | B9: SAP | C9: 6220 | D9: INST CAIXA MED CPREDE 1 MEDID ELETROM LM | E9: 143.58 | F9: 0 | G9: 0 | H9: 0
A10: 500 | B10: SAP | C10: 6227 | D10: DESAT CX MED CP-REDE P/ 3 OU 4 MEDID LM | E10: 0 | F10: 191.44 | G10: 0 | H10: 0
A11: 500 | B11: SAP | C11: 6235 | D11: INST CONEC RD SEC LM | E11: 9.58 | F11: 0 | G11: 0 | H11: 0
A12: 500 | B12: SAP | C12: 6252 | D12: SERV AB/FEC VAL ATER EM TERRA | E12: 17.23 | F12: 0 | G12: 0 | H12: 0
A13: 500 | B13: SAP | C13: 6281 | D13: DESAT ESTAI ANCORA CHUMBADO ROCHA LM | E13: 0 | F13: 95.72 | G13: 0 | H13: 0
... A579: 124 | B579: LINHA VIVA - ESTRUTURAS COMPLETAS | C579: 8091 | D579: INST SUP P/TRANSF <69KV LM | E579: 38.28 | F579: 0 | G579: 0 | H579: 0
C580: 8771 | D580: DESAT CH TRIP OLEO ABER CARGA < 69 KV LV | E580: 0 | F580: 373.54
C581: 92324 | D581: HORA DO COLABORADOR EM DISPONIBILIDADE PARA OUTRA REGIONAL - LM_x000D_ | E581: 87.11 | F581: 0

Sheet PADRAO
B3: EQUIPE=> | D3: ENCARREGADO: | J3: DATA SAÍDA=> | S3: DATA RETORNO=> | X3: TÉCNICO ENG:
B5: ENDEREÇO=> | W5: NR
B7: ELETRICISTAS=>
B9: SAIDA BASE => | H9: RETORNO BASE => | P9: =L9-D9+12 -> 12 | S9: KM INICIAL=> | AC9: KM | AD9: ;
B11: INICIO SERVIÇO => | H11: RETORNO SERVIÇO => | P11: =L11-D11+12 -> 12 | S11: KM FINAL=>
B13: CÓD. ACIONAMENTO=> | H13: Nº INTERVENÇÃO=> | R13: NOTA (SS)=> | X13: OS TABLET =>
B15: OBSERVAÇÃO =>
B17: TRANSFORMADOR RETIRADO POTENCIA => | J17: MARCA => | Q17: FABRICAÇÃO =>
B18: TENSÃO SEGUNDARIA=> | G18: V | H18: TENSÃO PRIMARIA=> | N18: KV | P18: Nº SERIE => | W18: PATRIMONIO =>
B20: TRANSFORMADOR INSTALADO POTENCIA => | J20: MARCA => | Q20: FABRICAÇÃO =>
B21: TENSÃO SEGUNDARIA=> | G21: V | H21: TENSÃO PRIMARIA=> | N21: KV | P21: Nº SERIE => | W21: PATRIMONIO =>
B22: A-N=> | D22: B-N=> | H22: C-N=> | J22: A-B=> | M22: A-C=> | P22: B-C=> | T22: A=> | V22: B=> | X22: C=> | AA22: N=>
B24: ALIMENTADOR => | D24: 003 | H24: SUBESTAÇÃO => | J24: 011 | M24: Nº TRANSFORMADOR => | U24: Nº ID POSTE => | W24: 36590316
B26: ITEM | C26: CÓD | D26: MÃO DE OBRA | V26: Un | W26: R$ | X26: OPERAÇÕES
Y27: Inst. | Z27: Ret. | AA27: TOTAL | AB27: R$
B28: 1 | C28: 10521 | D28: =IF(C28="","",VLOOKUP(C28,'MÃO OBRA'!A$2:G$581,2,FALSE)) -> SERV INSPECAO EM REDE RURAL LM | V28: =IF(C28="","",VLOOKUP(C28,'MÃO OBRA'!A$2:F$581,3,FALSE)) -> UN | W28: =IF(C28="","",VLOOKUP(C28,'MÃO OBRA'!A$2:F$581,6,FALSE)) -> 32.55 | X28: 1 | AA28: =X28 -> 1 | AB28: =IF(C28="","",(W28*AA28)) -> 32.55
B29: 2 | D29: =IF(C29="","",VLOOKUP(C29,'MÃO OBRA'!A$2:G$581,2,FALSE)) | V29: =IF(C29="","",VLOOKUP(C29,'MÃO OBRA'!A$2:F$581,3,FALSE)) | W29: =IF(C29="","",VLOOKUP(C29,'MÃO OBRA'!A$2:F$581,6,FALSE)) | AA29: =X29 -> 0 | AB29: =IF(C29="","",(W29*AA29))
B30: 3 | D30: =IF(C30="","",VLOOKUP(C30,'MÃO OBRA'!A$2:G$581,2,FALSE)) | V30: =IF(C30="","",VLOOKUP(C30,'MÃO OBRA'!A$2:F$581,3,FALSE)) | W30: =IF(C30="","",VLOOKUP(C30,'MÃO OBRA'!A$2:F$581,6,FALSE)) | AA30: =X30 -> 0 | AB30: =IF(C30="","",(W30*AA30))
B31: 4 | D31: =IF(C31="","",VLOOKUP(C31,'MÃO OBRA'!A$2:G$581,2,FALSE)) | V31: =IF(C31="","",VLOOKUP(C31,'MÃO OBRA'!A$2:F$581,3,FALSE)) | W31: =IF(C31="","",VLOOKUP(C31,'MÃO OBRA'!A$2:F$581,6,FALSE)) | AA31: =X31 -> 0 | AB31: =IF(C31="","",(W31*AA31))
B32: 5 | D32: =IF(C32="","",VLOOKUP(C32,'MÃO OBRA'!A$2:G$581,2,FALSE)) | V32: =IF(C32="","",VLOOKUP(C32,'MÃO OBRA'!A$2:F$581,3,FALSE)) | W32: =IF(C32="","",VLOOKUP(C32,'MÃO OBRA'!A$2:F$581,6,FALSE)) | AA32: =X32 -> 0 | AB32: =IF(C32="","",(W32*AA32))
B33: 6 | D33: =IF(C33="","",VLOOKUP(C33,'MÃO OBRA'!A$2:G$581,2,FALSE)) | V33: =IF(C33="","",VLOOKUP(C33,'MÃO OBRA'!A$2:F$581,3,FALSE)) | W33: =IF(C33="","",VLOOKUP(C33,'MÃO OBRA'!A$2:F$581,6,FALSE)) | AA33: =X33 -> 0 | AB33: =IF(C33="","",(W33*AA33))
B34: 7 | D34: =IF(C34="","",VLOOKUP(C34,'MÃO OBRA'!A$2:G$581,2,FALSE)) | V34: =IF(C34="","",VLOOKUP(C34,'MÃO OBRA'!A$2:F$581,3,FALSE)) | W34: =IF(C34="","",VLOOKUP(C34,'MÃO OBRA'!A$2:F$581,6,FALSE)) | AA34: =X34 -> 0 | AB34: =IF(C34="","",(W34*AA34))
B35: 8 | D35: =IF(C35="","",VLOOKUP(C35,'MÃO OBRA'!A$2:G$581,2,FALSE)) | V35: =IF(C35="","",VLOOKUP(C35,'MÃO OBRA'!A$2:F$581,3,FALSE)) | W35: =IF(C35="","",VLOOKUP(C35,'MÃO OBRA'!A$2:F$581,6,FALSE)) | AA35: =X35 -> 0 | AB35: =IF(C35="","",(W35*AA35))
B36: 9 | D36: =IF(C36="","",VLOOKUP(C36,'MÃO OBRA'!A$2:G$581,2,FALSE)) | V36: =IF(C36="","",VLOOKUP(C36,'MÃO OBRA'!A$2:F$581,3,FALSE)) | W36: =IF(C36="","",VLOOKUP(C36,'MÃO OBRA'!A$2:F$581,6,FALSE)) | AA36: =X36 -> 0 | AB36: =IF(C36="","",(W36*AA36))
B37: 10 | D37: =IF(C37="","",VLOOKUP(C37,'MÃO OBRA'!A$2:G$581,2,FALSE)) | V37: =IF(C37="","",VLOOKUP(C37,'MÃO OBRA'!A$2:F$581,3,FALSE)) | W37: =IF(C37="","",VLOOKUP(C37,'MÃO OBRA'!A$2:F$581,6,FALSE)) | AA37: =X37 -> 0 | AB37: =IF(C37="","",(W37*AA37))
B38: 11 | D38: =IF(C38="","",VLOOKUP(C38,'MÃO OBRA'!A$2:G$581,2,FALSE)) | V38: =IF(C38="","",VLOOKUP(C38,'MÃO OBRA'!A$2:F$581,3,FALSE)) | W38: =IF(C38="","",VLOOKUP(C38,'MÃO OBRA'!A$2:F$581,6,FALSE)) | AA38: =X38 -> 0 | AB38: =IF(C38="","",(W38*AA38))
B39: 12 | D39: =IF(C39="","",VLOOKUP(C39,'MÃO OBRA'!A$2:G$581,2,FALSE)) | V39: =IF(C39="","",VLOOKUP(C39,'MÃO OBRA'!A$2:F$581,3,FALSE)) | W39: =IF(C39="","",VLOOKUP(C39,'MÃO OBRA'!A$2:F$581,6,FALSE)) | AA39: =X39 -> 0 | AB39: =IF(C39="","",(W39*AA39))
B40: 13 | D40: =IF(C40="","",VLOOKUP(C40,'MÃO OBRA'!A$2:G$581,2,FALSE)) | V40: =IF(C40="","",VLOOKUP(C40,'MÃO OBRA'!A$2:F$581,3,FALSE)) | W40: =IF(C40="","",VLOOKUP(C40,'MÃO OBRA'!A$2:F$581,6,FALSE)) | AA40: =X40 -> 0 | AB40: =IF(C40="","",(W40*AA40))
B41: 14 | D41: =IF(C41="","",VLOOKUP(C41,'MÃO OBRA'!A$2:G$581,2,FALSE)) | V41: =IF(C41="","",VLOOKUP(C41,'MÃO OBRA'!A$2:F$581,3,FALSE)) | W41: =IF(C41="","",VLOOKUP(C41,'MÃO OBRA'!A$2:F$581,6,FALSE)) | AA41: =X41 -> 0 | AB41: =IF(C41="","",(W41*AA41))
AB42: =SUM(AB28:AC41) -> 32.55
W43: =IF(X43>0,(243.02),"")
B44: 26376 | D44: SERV. EMERG. FORA DO HORARIO COMERCIAL-ADICIONAL 30% | V44: ADIC | W44: =IF(X44>0,(AB42*0.3),"0") -> 0 | AB44: =X44*W44 -> 0
B45: 92525 | D45: SERV. EMERG. HORARIO COMERCIAL - ADICIONAL 12% | V45: ADIC | W45: =IF(X45>0,(AB42*0.12),"0") -> 3.906 | X45: 1 | AB45: =X45*W45 -> 3.906
B46: 0 | AB46: =SUM(AB42:AC45) -> 36.456
B47: ITEM | C47: CÓD | D47: MATERIAL APLICADO | W47: UN | X47: OPERAÇÕES
Z48: =Z27 -> Ret. | AA48: TOTAL
B49: 1 | D49: =IF(C49="","",VLOOKUP(C49,MATERIAL!A:C,2,FALSE)) | W49: =IF(C49="","",VLOOKUP(C49,MATERIAL!A$3:C$528,3,FALSE)) | AA49: =SUM(X49:Z49) -> 0 | AB49: =IF(C49="","",(X49))
B50: 2 | D50: =IF(C50="","",VLOOKUP(C50,MATERIAL!A:C,2,FALSE)) | W50: =IF(C50="","",VLOOKUP(C50,MATERIAL!A$3:C$528,3,FALSE)) | AA50: =SUM(X50:Z50) -> 0 | AB50: =IF(C50="","",(X50))
B51: 3 | D51: =IF(C51="","",VLOOKUP(C51,MATERIAL!A:C,2,FALSE)) | W51: =IF(C51="","",VLOOKUP(C51,MATERIAL!A$3:C$528,3,FALSE)) | AA51: =SUM(X51:Z51) -> 0 | AB51: =IF(C51="","",(X51))
B52: 4 | D52: =IF(C52="","",VLOOKUP(C52,MATERIAL!A:C,2,FALSE)) | W52: =IF(C52="","",VLOOKUP(C52,MATERIAL!A$3:C$528,3,FALSE)) | AA52: =SUM(X52:Z52) -> 0 | AB52: =IF(C52="","",(X52))
...

Sheet MÃO OBRA
A1: CÓDIGOS SIAGO | B1: DESCRIÇÃO BÁSICA | C1: U N | D1: VALOR | E1: T/H | F1: VALOR R$ 2021 | G1: Nº CONTRATO | H1: Inst. | I1: Ret.
A2: 4595 | B2: Alteração de US - Item a ser utilizado para pagamento da diferença na medição de mão de obra quando houver ajuste no valor da US. | C2: UN | E2: 0.20006858 | F2: 1 | G2: 2024014901 | H2: x
A3: 6042 | B3: DESAT CHAVE FUSIVEL < 34,5 KV LM | C3: UN | E3: 2.9900566 | F3: 28.72 | G3: 2024014901 | H3: x
A4: 6043 | B4: DESAT CHAVE FUSIVEL => 34,5 KV LM | F4: 28.72 | G4: 2024014901
A5: 6046 | B5: DESAT CHAVE FUSIVEL 3 OP < 34,5 KV | C5: UN | D5: 9.74 | E5: 12 | F5: 38.28 | G5: 2021014001 | H5: x
A6: 6047 | B6: DESAT CHAVE FUSIVEL 3 OP => 34,5 KV | C6: UN | D6: 48.71 | E6: 7.5000857 | F6: 38.28 | G6: 2024014901 | H6: x
A7: 6055 | B7: DESAT PARA-RAIOS RD < 34,5 KV LM | F7: 28.72 | G7: 2024014901
A8: 6056 | B8: DESAT TRANSF DIST AEREO MONOFASICO LM | C8: UN | D8: 162.36 | E8: 1 | F8: 191.44 | G8: 2024014901 | H8: x
A9: 6061 | B9: DESAT TRANSF DISTRIBUIC AEREO 3F LM | F9: 287.17 | G9: 2024014901
A10: 6062 | B10: DESATIVAR CHAVE SECC FACA => 15 KV LM | F10: 28.72 | G10: 2024014901
A11: 6069 | B11: INST CH SECC S/LAM TER MONO MAN <69KV | F11: 95.72 | G11: 2024014901
A12: 6071 | B12: INST CHAVE FUSIVEL < 34,5 KV LM | C12: UN | E12: 7.1500086 | F12: 95.72 | G12: 2021014001 | H12: x
A13: 6072 | B13: INST CHAVE FUSIVEL => 34,5KV LM | C13: UN | D13: 162.36 | E13: 1.9699983 | F13: 95.72 | G13: 2024014901 | H13: x | I13: x
A14: 6073 | B14: INST CHAVE FUSIVEL 3 OP < 34,5 KV | C14: UN | E14: 66 | F14: 124.44 | G14: 2021014001 | H14: x
A15: 6074 | B15: INST CHAVE FUSIVEL 3 OP => 34,5 KV | C15: UN | D15: 97.42 | E15: 1.5000857 | F15: 124.44 | G15: 2021014001 | H15: x
A16: 6082 | B16: INST PARA-RAIOS RD < 34,5 KV LM | C16: UN | D16: 185.09 | E16: 54.669981 | F16: 95.72 | G16: 2024014901 | H16: x
A17: 6083 | B17: INST PARA-RAIOS RD => 34,5 KV LM | C17: UN | D17: 73.06 | E17: 4 | F17: 95.72 | G17: 2021014001 | H17: x
A18: 6092 | B18: INST TRANSF DISTRIBUIC AEREO MONO LM | C18: UN | D18: 974.16 | E18: 46 | F18: 765.78 | G18: 2024014901 | H18: x
A19: 6093 | B19: INST TRANSF DISTRIBUIC AEREO TRIF LM | C19: UN | E19: 56 | F19: 1052.94 | G19: 2024014901 | H19: x
A20: 6102 | B20: SUBST PARA-RAIO RD <34,5KV LV | C20: UN | D20: 2435.4 | E20: 2 | F20: 166.37 | G20: 2024014901 | I20: x
A21: 6128 | B21: LIMP FAIXA CERRADO E CAPOEIRA | C21: UN | D21: 243.54 | E21: 26.599863 | F21: 1544 | G21: 2024014901 | H21: x | I21: x
A22: 6129 | B22: LIMP FAIXA VEGETACAO DENSA | C22: UN | E22: 2 | F22: 2105.89 | G22: 2024014901 | I22: x
A23: 6133 | B23: DISP H-MAQ P/EXEC SERV LM | C23: UN | D23: 2435.4 | E23: 0.50008572 | F23: 974.45 | G23: 2024014901 | I23: x
A24: 6137 | B24: LIMP FAIXA SERVIDAO MECANIZADA | C24: UN | E24: 14.200069 | F24: 2758.72 | G24: 2021014001 | H24: x
A25: 6151 | B25: DESLOC EQUIP PESADA ACIMA 50 KM DA BASE | F25: 5.75 | G25: 2024014901
A26: 6155 | B26: SERV OFIC PODAR ARVORE RURAL LM | F26: 67 | G26: 2024014901
A27: 6156 | B27: PODAR ARV GRANDE LM | F27: 67 | G27: 2024014901
A28: 6169 | B28: LIMP FAIXA CAMPO-10M LARGURA | F28: 1052.94 | G28: 2024014901
A29: 6170 | B29: OPER CHAVE FACA AB E FC EMERG LM | C29: UN | D29: 77.93 | E29: 0.18001029 | F29: 47.86 | G29: 2024014901 | H29: x
A30: 6171 | B30: OPER CHAVE FUS AB E FC EMERG LM | C30: UN | D30: 73.06 | E30: 28 | F30: 47.86 | G30: 2024014901 | H30: x
A31: 6181 | B31: SERVIÇO EXCLUSIVO DE PODA DE ARVORE URB/RUR C/RECOLHA | C31: UN | E31: 0.27995885 | F31: 69.88 | G31: 2024014901 | H31: x | I31: x
A32: 6182 | B32: SERVIÇO EXCLUSIVO DE PODA DE ARVORE URB/RUR S/RECOLHA | C32: UN | D32: 64.94 | E32: 0.50008572 | F32: 47.86 | G32: 2024014901 | I32: x
A33: 6195 | B33: INST MED MEDIA TENSAO CONJ TCS E TPS | F33: 1052.94 | G33: 2024014901
A34: 6196 | B34: INST PADR ENERG TRIF T5/T6/T7-INDIR LM | C34: UN | E34: 0.50008572 | F34: 1531.56 | G34: 2024014901 | I34: x
A35: 6210 | B35: EFET RECUPER CX CP REDE LM | C35: UN | D35: 232.17 | E35: 0.50008572 | F35: 7.66 | G35: 2024014901 | I35: x
A36: 6212 | B36: DESAT MED EM CAIXA CP-REDE BIFASICO LM | F36: 81.36 | G36: 2024014901
A37: 6213 | B37: DESAT MED EM CAIXA CP-REDE TRIFASICO LM | C37: UN | D37: 211.07 | E37: 0.50008572 | F37: 119.66 | G37: 2024014901 | I37: x
A38: 6216 | B38: INS RAMAL ENTR C/ELETR CX CP RD LM | C38: UN | D38: 405.9 | E38: 2.9900566 | F38: 114.86 | G38: 2024014901 | H38: x
A39: 6217 | B39: DESAT MED EM CAIXA CP-TRAFO LM | C39: UN | E39: 0.54997428 | F39: 105.3 | G39: 2024014901 | H39: x | I39: x
A40: 6220 | B40: INST CAIXA MED CPREDE 1 MEDID ELETROM LM | C40: UN | E40: 2 | F40: 143.58 | G40: 2021014001 | H40: x
...

Sheet FECHAMENTO
M1: =SUM(N4:N688) -> 0
A3: LOTE ENVIADO | B3: DATA ENVIO LOTE | C3: Nº CONTRATO | D3: DATA EXECUÇÃO | E3: EQUIPE | F3: ENCARREGADO | G3: IDENTIFICAÇÃO EQUIPAMENTO | H3: OS COI | I3: OS PRIMARIA | J3: OS SECUNDARIA | K3: CONTROLE CRS | L3: Apoio Linha Viva | M3: Nº DA OBRA EMERGENCIAL | N3: VALOR CRS | O3: VALOR NÚCLEO | P3: DIFERENÇA | Q3: OBSERVAÇÕES ENERGISA | R3: OBSERVAÇÕES DINAMO

Sheet Obras
A1: LOTE ENVIADO | B1: DATA ENVIO LOTE | C1: Nº CONTRATO | D1: DATA EXECUÇÃO | E1: EQUIPE | F1: ENCARREGADO | G1: IDENTIFICAÇÃO EQUIPAMENTO | H1: OS COI | I1: OS PRIMARIA | J1: OS SECUNDARIA | K1: CONTROLE CRS | L1: Apoio Linha Viva | M1: Nº DA OBRA EMERGENCIAL | N1: VALOR CRS | O1: VALOR NÚCLEO | P1: DIFERENÇA | Q1: OBSERVAÇÕES ENERGISA | R1: OBSERVAÇÕES DINAMO

Sheet 5716677005
A2: EQUIPE=> | B2: 96 | C2: ENCARREGADO: | G2: ELIEZER | I2: DATA SAÍDA=> | L2: Segunda-feira, 2 de maio de 2022 | R2: DATA RETORNO=> | S2: Segunda-feira, 2 de maio de 2022 | W2: TÉCNICO DIN: | Z2: ARINEY
A4: ENDEREÇO=> | C4: Rua Radialista Reinaldo Veiga, 8 - Coophamil, Cuiabá - MT, 78028-180 | V4: NR | X4: DINEM20220***
A6: ELETRICISTAS=> | C6: JOILSON / RONILSON
A8: SAIDA BASE => | C8: 08:35 | G8: RETORNO BASE => | K8: 0.73958333 | O8: =K8-C8 -> 0.38194444 | R8: KM INICIAL=> | T8: 59600 | V8: =T10-T8 -> 30 | AB8: KM
A10: INICIO SERVIÇO => | C10: 10:45 | G10: RETORNO SERVIÇO => | K10: 0.68055556 | O10: =K10-C10 -> 0.23263889 | R10: KM FINAL=> | T10: 59630
A12: CÓD. ACIONAMENTO=> | G12: Nº INTERVENÇÃO=> | J12: 20222986520197 | Q12: NOTA (SS)=> | S12: EMT-RD-ME002901/2022 | W12: OS TABLET =>
A14: OBSERVAÇÃO =>
A16: TRANSFORMADOR RETIRADO POTENCIA => | G16: 75 KVA | I16: MARCA => | L16: WEG | P16: FABRICAÇÃO => | R16: 12 / 1990
A17: TENSÃO SEGUNDARIA=> | C17: 127/220 | F17: V | G17: TENSÃO PRIMARIA=> | J17: 44786 | M17: KV | O17: Nº SERIE => | R17: 73799 | V17: PATRIMONIO => | Y17: N/A
A19: TRANSFORMADOR INSTALADO POTENCIA => | G19: 112,5 KVA | I19: MARCA => | L19: ITAIPU | P19: FABRICAÇÃO => | R19: 02 / 2022
A20: TENSÃO SEGUNDARIA=> | C20: 127/220 | F20: V | G20: TENSÃO PRIMARIA=> | J20: 44786 | M20: KV | O20: Nº SERIE => | R20: 452882 | V20: PATRIMONIO => | Y20: 275400
A21: A-N=> | B21: 120 | C21: B-N=> | E21: 122 | G21: C-N=> | H21: 126 | I21: A-B=> | K21: 225 | L21: A-C=> | M21: 215 | O21: B-C=> | Q21: 218 | S21: A=> | T21: 38 | U21: B=> | V21: 20 | W21: C=> | X21: 38 | Z21: N=> | AA21: 16
A23: ALIMENTADOR => | G23: SUBESTAÇÃO => | L23: Nº TRANSFORMADOR => | Q23: 5716677005 | T23: Nº ID POSTE =>
A25: ITEM | B25: CÓD | U25: Un | V25: R$ | W25: OPERAÇÕES
X26: Inst. | Y26: Ret. | Z26: TOTAL | AA26: R$
A27: 1 | B27: 6061 | C27: =IF(B27="","",VLOOKUP(B27,'MÃO OBRA'!A$2:G$436,2,FALSE)) -> DESAT TRANSF DISTRIBUIC AEREO 3F LM | U27: =IF(B27="","",VLOOKUP(B27,'MÃO OBRA'!A$2:F$35064,3,FALSE)) -> 0 | V27: =IF(B27="","",VLOOKUP(B27,'MÃO OBRA'!A$2:F$21664,6,FALSE)) -> 287.17 | W27: 1 | X27: =IFERROR(VLOOKUP(B27,'MÃO OBRA'!A:H,8,FALSE),"") -> 0 | Y27: =IFERROR(VLOOKUP(B27,'MÃO OBRA'!A:I,9,FALSE),"") -> 0 | Z27: =W27 -> 1 | AA27: =IF(B27="","",(V27*Z27)) -> 287.17
A28: =A27+1 -> 2 | B28: 6093 | C28: =IF(B28="","",VLOOKUP(B28,'MÃO OBRA'!A$2:G$436,2,FALSE)) -> INST TRANSF DISTRIBUIC AEREO TRIF LM | U28: =IF(B28="","",VLOOKUP(B28,'MÃO OBRA'!A$2:F$35064,3,FALSE)) -> UN | V28: =IF(B28="","",VLOOKUP(B28,'MÃO OBRA'!A$2:F$21664,6,FALSE)) -> 1052.94 | W28: 1 | X28: =IFERROR(VLOOKUP(B28,'MÃO OBRA'!A:H,8,FALSE),"") -> x | Y28: =IFERROR(VLOOKUP(B28,'MÃO OBRA'!A:I,9,FALSE),"") -> 0 | Z28: =W28 -> 1 | AA28: =IF(B28="","",(V28*Z28)) -> 1052.94
A29: =A28+1 -> 3 | B29: 7038 | C29: =IF(B29="","",VLOOKUP(B29,'MÃO OBRA'!A$2:G$436,2,FALSE)) -> #N/A | U29: =IF(B29="","",VLOOKUP(B29,'MÃO OBRA'!A$2:F$35064,3,FALSE)) -> UN | V29: =IF(B29="","",VLOOKUP(B29,'MÃO OBRA'!A$2:F$21664,6,FALSE)) -> 124.44 | W29: 1 | X29: =IFERROR(VLOOKUP(B29,'MÃO OBRA'!A:H,8,FALSE),"") -> 0 | Y29: =IFERROR(VLOOKUP(B29,'MÃO OBRA'!A:I,9,FALSE),"") -> x | Z29: =W29 -> 1 | AA29: =IF(B29="","",(V29*Z29)) -> 124.44
A30: =A29+1 -> 4 | B30: 6171 | C30: =IF(B30="","",VLOOKUP(B30,'MÃO OBRA'!A$2:G$436,2,FALSE)) -> OPER CHAVE FUS AB E FC EMERG LM | U30: =IF(B30="","",VLOOKUP(B30,'MÃO OBRA'!A$2:F$35064,3,FALSE)) -> UN | V30: =IF(B30="","",VLOOKUP(B30,'MÃO OBRA'!A$2:F$21664,6,FALSE)) -> 47.86 | W30: 3 | X30: =IFERROR(VLOOKUP(B30,'MÃO OBRA'!A:H,8,FALSE),"") -> x | Y30: =IFERROR(VLOOKUP(B30,'MÃO OBRA'!A:I,9,FALSE),"") -> 0 | Z30: =W30 -> 3 | AA30: =IF(B30="","",(V30*Z30)) -> 143.58
A31: =A30+1 -> 5 | B31: 6501 | C31: =IF(B31="","",VLOOKUP(B31,'MÃO OBRA'!A$2:G$436,2,FALSE)) -> SUBST ELO FUSIVEL LM | U31: =IF(B31="","",VLOOKUP(B31,'MÃO OBRA'!A$2:F$35064,3,FALSE)) -> 0 | V31: =IF(B31="","",VLOOKUP(B31,'MÃO OBRA'!A$2:F$21664,6,FALSE)) -> 47.86 | W31: 3 | X31: =IFERROR(VLOOKUP(B31,'MÃO OBRA'!A:H,8,FALSE),"") -> 0 | Y31: =IFERROR(VLOOKUP(B31,'MÃO OBRA'!A:I,9,FALSE),"") -> 0 | Z31: =W31 -> 3 | AA31: =IF(B31="","",(V31*Z31)) -> 143.58
A32: 6 | B32: 6082 | C32: =IF(B32="","",VLOOKUP(B32,'MÃO OBRA'!A$2:G$436,2,FALSE)) -> INST PARA-RAIOS RD < 34,5 KV LM | U32: =IF(B32="","",VLOOKUP(B32,'MÃO OBRA'!A$2:F$35064,3,FALSE)) -> UN | V32: =IF(B32="","",VLOOKUP(B32,'MÃO OBRA'!A$2:F$21664,6,FALSE)) -> 95.72 | W32: 3 | X32: =IFERROR(VLOOKUP(B32,'MÃO OBRA'!A:H,8,FALSE),"") -> x | Y32: =IFERROR(VLOOKUP(B32,'MÃO OBRA'!A:I,9,FALSE),"") -> 0 | Z32: =W32 -> 3 | AA32: =IF(B32="","",(V32*Z32)) -> 287.16
A33: =A32+1 -> 7 | B33: 6083 | C33: =IF(B33="","",VLOOKUP(B33,'MÃO OBRA'!A$2:G$436,2,FALSE)) -> INST PARA-RAIOS RD => 34,5 KV LM | U33: =IF(B33="","",VLOOKUP(B33,'MÃO OBRA'!A$2:F$35064,3,FALSE)) -> UN | V33: =IF(B33="","",VLOOKUP(B33,'MÃO OBRA'!A$2:F$21664,6,FALSE)) -> 95.72 | W33: 3 | X33: =IFERROR(VLOOKUP(B33,'MÃO OBRA'!A:H,8,FALSE),"") -> x | Y33: =IFERROR(VLOOKUP(B33,'MÃO OBRA'!A:I,9,FALSE),"") -> 0 | Z33: =W33 -> 3 | AA33: =IF(B33="","",(V33*Z33)) -> 287.16
A34: =A33+1 -> 8 | B34: 6235 | C34: =IF(B34="","",VLOOKUP(B34,'MÃO OBRA'!A$2:G$436,2,FALSE)) -> INST CONEC RD SEC LM | U34: =IF(B34="","",VLOOKUP(B34,'MÃO OBRA'!A$2:F$35064,3,FALSE)) -> UN | V34: =IF(B34="","",VLOOKUP(B34,'MÃO OBRA'!A$2:F$21664,6,FALSE)) -> 9.58 | W34: 8 | X34: =IFERROR(VLOOKUP(B34,'MÃO OBRA'!A:H,8,FALSE),"") -> x | Y34: =IFERROR(VLOOKUP(B34,'MÃO OBRA'!A:I,9,FALSE),"") -> 0 | Z34: =W34 -> 8 | AA34: =IF(B34="","",(V34*Z34)) -> 76.64
A35: =A34+1 -> 9 | B35: 6055 | C35: =IF(B35="","",VLOOKUP(B35,'MÃO OBRA'!A$2:G$436,2,FALSE)) -> DESAT PARA-RAIOS RD < 34,5 KV LM | U35: =IF(B35="","",VLOOKUP(B35,'MÃO OBRA'!A$2:F$35064,3,FALSE)) -> 0 | V35: =IF(B35="","",VLOOKUP(B35,'MÃO OBRA'!A$2:F$21664,6,FALSE)) -> 28.72 | W35: 3 | X35: =IFERROR(VLOOKUP(B35,'MÃO OBRA'!A:H,8,FALSE),"") -> 0 | Y35: =IFERROR(VLOOKUP(B35,'MÃO OBRA'!A:I,9,FALSE),"") -> 0 | Z35: =W35 -> 3 | AA35: =IF(B35="","",(V35*Z35)) -> 86.16
A36: =A35+1 -> 10 | B36: 7640 | C36: =IF(B36="","",VLOOKUP(B36,'MÃO OBRA'!A$2:G$436,2,FALSE)) -> #N/A | U36: =IF(B36="","",VLOOKUP(B36,'MÃO OBRA'!A$2:F$35064,3,FALSE)) -> 0 | V36: =IF(B36="","",VLOOKUP(B36,'MÃO OBRA'!A$2:F$21664,6,FALSE)) -> 19.14 | W36: 8 | X36: =IFERROR(VLOOKUP(B36,'MÃO OBRA'!A:H,8,FALSE),"") -> 0 | Y36: =IFERROR(VLOOKUP(B36,'MÃO OBRA'!A:I,9,FALSE),"") -> 0 | Z36: =W36 -> 8 | AA36: =IF(B36="","",(V36*Z36)) -> 153.12
A37: =A36+1 -> 11 | C37: =IF(B37="","",VLOOKUP(B37,'MÃO OBRA'!A$2:G$436,2,FALSE)) | U37: =IF(B37="","",VLOOKUP(B37,'MÃO OBRA'!A$2:F$35064,3,FALSE)) | V37: =IF(B37="","",VLOOKUP(B37,'MÃO OBRA'!A$2:F$21664,6,FALSE)) | X37: =IFERROR(VLOOKUP(B37,'MÃO OBRA'!A:H,8,FALSE),"") | Y37: =IFERROR(VLOOKUP(B37,'MÃO OBRA'!A:I,9,FALSE),"") | Z37: =W37 -> 0 | AA37: =IF(B37="","",(V37*Z37))
A38: =A37+1 -> 12 | C38: =IF(B38="","",VLOOKUP(B38,'MÃO OBRA'!A$2:G$436,2,FALSE)) | U38: =IF(B38="","",VLOOKUP(B38,'MÃO OBRA'!A$2:F$35064,3,FALSE)) | V38: =IF(B38="","",VLOOKUP(B38,'MÃO OBRA'!A$2:F$21664,6,FALSE)) | X38: =IFERROR(VLOOKUP(B38,'MÃO OBRA'!A:H,8,FALSE),"") | Y38: =IFERROR(VLOOKUP(B38,'MÃO OBRA'!A:I,9,FALSE),"") | Z38: =W38 -> 0 | AA38: =IF(B38="","",(V38*Z38))
A39: =A38+1 -> 13 | C39: =IF(B39="","",VLOOKUP(B39,'MÃO OBRA'!A$2:G$436,2,FALSE)) | U39: =IF(B39="","",VLOOKUP(B39,'MÃO OBRA'!A$2:F$35064,3,FALSE)) | V39: =IF(B39="","",VLOOKUP(B39,'MÃO OBRA'!A$2:F$21664,6,FALSE)) | X39: =IFERROR(VLOOKUP(B39,'MÃO OBRA'!A:H,8,FALSE),"") | Y39: =IFERROR(VLOOKUP(B39,'MÃO OBRA'!A:I,9,FALSE),"") | Z39: =W39 -> 0 | AA39: =IF(B39="","",(V39*Z39))
A40: =A39+1 -> 14 | C40: =IF(B40="","",VLOOKUP(B40,'MÃO OBRA'!A$2:G$436,2,FALSE)) | V40: =IF(B40="","",VLOOKUP(B40,'MÃO OBRA'!A$2:F$21664,6,FALSE)) | X40: =IFERROR(VLOOKUP(B40,'MÃO OBRA'!A:H,8,FALSE),"") | Y40: =IFERROR(VLOOKUP(B40,'MÃO OBRA'!A:I,9,FALSE),"") | Z40: =W40 -> 0 | AA40: =IF(B40="","",(V40*Z40))
A41: =A40+1 -> 15 | C41: =IF(B41="","",VLOOKUP(B41,'MÃO OBRA'!A$2:G$436,2,FALSE)) | U41: =IF(B41="","",VLOOKUP(B41,'MÃO OBRA'!A$2:F$35064,3,FALSE)) | V41: =IF(B41="","",VLOOKUP(B41,'MÃO OBRA'!A$2:F$21664,6,FALSE)) | X41: =IFERROR(VLOOKUP(B41,'MÃO OBRA'!A:H,8,FALSE),"") | Y41: =IFERROR(VLOOKUP(B41,'MÃO OBRA'!A:I,9,FALSE),"") | Z41: =W41 -> 0 | AA41: =IF(B41="","",(V41*Z41))
A42: =A41+1 -> 16 | C42: =IF(B42="","",VLOOKUP(B42,'MÃO OBRA'!A$2:G$436,2,FALSE)) | U42: =IF(B42="","",VLOOKUP(B42,'MÃO OBRA'!A$2:F$35064,3,FALSE)) | V42: =IF(B42="","",VLOOKUP(B42,'MÃO OBRA'!A$2:F$21664,6,FALSE)) | X42: =IFERROR(VLOOKUP(B42,'MÃO OBRA'!A:H,8,FALSE),"") | Y42: =IFERROR(VLOOKUP(B42,'MÃO OBRA'!A:I,9,FALSE),"") | Z42: =W42 -> 0 | AA42: =IF(B42="","",(V42*Z42))
A43: =A42+1 -> 17 | C43: =IF(B43="","",VLOOKUP(B43,'MÃO OBRA'!A$2:G$436,2,FALSE)) | U43: =IF(B43="","",VLOOKUP(B43,'MÃO OBRA'!A$2:F$35064,3,FALSE)) | V43: =IF(B43="","",VLOOKUP(B43,'MÃO OBRA'!A$2:F$21664,6,FALSE)) | X43: =IFERROR(VLOOKUP(B43,'MÃO OBRA'!A:H,8,FALSE),"") | Y43: =IFERROR(VLOOKUP(B43,'MÃO OBRA'!A:I,9,FALSE),"") | Z43: =W43 -> 0 | AA43: =IF(B43="","",(V43*Z43))
A44: =A43+1 -> 18 | C44: =IF(B44="","",VLOOKUP(B44,'MÃO OBRA'!A$2:G$436,2,FALSE)) | U44: =IF(B44="","",VLOOKUP(B44,'MÃO OBRA'!A$2:F$35064,3,FALSE)) | V44: =IF(B44="","",VLOOKUP(B44,'MÃO OBRA'!A$2:F$21664,6,FALSE)) | X44: =IFERROR(VLOOKUP(B44,'MÃO OBRA'!A:H,8,FALSE),"") | Y44: =IFERROR(VLOOKUP(B44,'MÃO OBRA'!A:I,9,FALSE),"") | Z44: =W44 -> 0 | AA44: =IF(B44="","",(V44*Z44))
A45: SUB-TOTAL | AA45: =SUM(AA27:AB44) -> 2641.95
A46: 26378 | C46: SERV. EMERG. MOBILIZAÇÃO/DESMOBILIZAÇÃO (1 HORA) | U46: HORA | V46: =IF(W46>0,(243.02),"") | AA46: =V46*W46 -> #VALUE!
A47: 26376 | C47: SERV. EMERG. FORA DO HORARIO COMERCIAL-ADICIONAL 30% | U47: ADIC | V47: =IF(W47>0,(AA45*0.3),"") | AA47: =V47*W47 -> #VALUE!
A48: 26377 | C48: SERV. EMERG. DOMINGO E FERIADO - ADICIONAL 50% | U48: ADIC | V48: =IF(W48>0,(AA45*0.5),"") | AA48: =V48*W48 -> #VALUE!
A49: TOTAL | AA49: =SUM(AA45:AB48) -> #VALUE!
A50: ITEM | B50: CÓD | C50: MATERIAL APLICADO | V50: UN | W50: OPERAÇÕES
Y51: =Y26 -> Ret. | Z51: TOTAL
...

Sheet 5702814005 4575
A2: EQUIPE=> | B2: 147 | C2: ENCARREGADO: | G2: FERNANDO | I2: DATA SAÍDA=> | L2: Terça-feira, 3 de maio de 2022 | R2: DATA RETORNO=> | S2: Terça-feira, 3 de maio de 2022 | W2: TÉCNICO DIN: | Z2: ARINEY
A4: ENDEREÇO=> | C4: Av. Flamboiant, 2-118 - Res. Sao Carlos, Cuiabá - MT, 78051-035 | V4: NR | X4: DINEM20220***
A6: ELETRICISTAS=> | C6: GESSER / LUCICLAUDIO
A8: SAIDA BASE => | C8: 08:35 | G8: RETORNO BASE => | K8: 0.73958333 | O8: =K8-C8 -> 0.38194444 | R8: KM INICIAL=> | T8: 59600 | V8: =T10-T8 -> 30 | AB8: KM
A10: INICIO SERVIÇO => | C10: 10:45 | G10: RETORNO SERVIÇO => | K10: 0.50069444 | O10: =K10-C10 -> 0.052777778 | R10: KM FINAL=> | T10: 59630
A12: CÓD. ACIONAMENTO=> | G12: Nº INTERVENÇÃO=> | J12: 20222986520197 | Q12: NOTA (SS)=> | S12: EMT-RD-ME002901/2022 | W12: OS TABLET =>
A14: OBSERVAÇÃO =>
A16: TRANSFORMADOR RETIRADO POTENCIA => | G16: 45 KVA | I16: MARCA => | L16: WEG | P16: FABRICAÇÃO => | R16: 07 / 1992
A17: TENSÃO SEGUNDARIA=> | C17: 127/220 | F17: V | G17: TENSÃO PRIMARIA=> | J17: 44786 | M17: KV | O17: Nº SERIE => | R17: 81439 | V17: PATRIMONIO => | Y17: 10004
A19: TRANSFORMADOR INSTALADO POTENCIA => | G19: 75 KVA | I19: MARCA => | L19: ITAIPU | P19: FABRICAÇÃO => | R19: 06 / 2021
A20: TENSÃO SEGUNDARIA=> | C20: 127/220 | F20: V | G20: TENSÃO PRIMARIA=> | J20: 44786 | M20: KV | O20: Nº SERIE => | R20: 435805 | V20: PATRIMONIO => | Y20: 270154
A21: A-N=> | B21: 120 | C21: B-N=> | E21: 122 | G21: C-N=> | H21: 126 | I21: A-B=> | K21: 225 | L21: A-C=> | M21: 215 | O21: B-C=> | Q21: 218 | S21: A=> | T21: 38 | U21: B=> | V21: 20 | W21: C=> | X21: 38 | Z21: N=> | AA21: 16
A23: ALIMENTADOR => | G23: SUBESTAÇÃO => | L23: Nº TRANSFORMADOR => | Q23: 5702814005 | T23: Nº ID POSTE =>
A25: ITEM | B25: CÓD | U25: Un | V25: R$ | W25: OPERAÇÕES
X26: Inst. | Y26: Ret. | Z26: TOTAL | AA26: R$
A27: 1 | B27: 6061 | C27: =IF(B27="","",VLOOKUP(B27,'MÃO OBRA'!A$2:G$436,2,FALSE)) -> DESAT TRANSF DISTRIBUIC AEREO 3F LM | U27: =IF(B27="","",VLOOKUP(B27,'MÃO OBRA'!A$2:F$35064,3,FALSE)) -> 0 | V27: =IF(B27="","",VLOOKUP(B27,'MÃO OBRA'!A$2:F$21664,6,FALSE)) -> 287.17 | W27: 1 | X27: =IFERROR(VLOOKUP(B27,'MÃO OBRA'!A:H,8,FALSE),"") -> 0 | Y27: =IFERROR(VLOOKUP(B27,'MÃO OBRA'!A:I,9,FALSE),"") -> 0 | Z27: =W27 -> 1 | AA27: =IF(B27="","",(V27*Z27)) -> 287.17
A28: =A27+1 -> 2 | B28: 6093 | C28: =IF(B28="","",VLOOKUP(B28,'MÃO OBRA'!A$2:G$436,2,FALSE)) -> INST TRANSF DISTRIBUIC AEREO TRIF LM | U28: =IF(B28="","",VLOOKUP(B28,'MÃO OBRA'!A$2:F$35064,3,FALSE)) -> UN | V28: =IF(B28="","",VLOOKUP(B28,'MÃO OBRA'!A$2:F$21664,6,FALSE)) -> 1052.94 | W28: 1 | X28: =IFERROR(VLOOKUP(B28,'MÃO OBRA'!A:H,8,FALSE),"") -> x | Y28: =IFERROR(VLOOKUP(B28,'MÃO OBRA'!A:I,9,FALSE),"") -> 0 | Z28: =W28 -> 1 | AA28: =IF(B28="","",(V28*Z28)) -> 1052.94
A29: =A28+1 -> 3 | B29: 7038 | C29: =IF(B29="","",VLOOKUP(B29,'MÃO OBRA'!A$2:G$436,2,FALSE)) -> #N/A | U29: =IF(B29="","",VLOOKUP(B29,'MÃO OBRA'!A$2:F$35064,3,FALSE)) -> UN | V29: =IF(B29="","",VLOOKUP(B29,'MÃO OBRA'!A$2:F$21664,6,FALSE)) -> 124.44 | W29: 1 | X29: =IFERROR(VLOOKUP(B29,'MÃO OBRA'!A:H,8,FALSE),"") -> 0 | Y29: =IFERROR(VLOOKUP(B29,'MÃO OBRA'!A:I,9,FALSE),"") -> x | Z29: =W29 -> 1 | AA29: =IF(B29="","",(V29*Z29)) -> 124.44
A30: =A29+1 -> 4 | B30: 6171 | C30: =IF(B30="","",VLOOKUP(B30,'MÃO OBRA'!A$2:G$436,2,FALSE)) -> OPER CHAVE FUS AB E FC EMERG LM | U30: =IF(B30="","",VLOOKUP(B30,'MÃO OBRA'!A$2:F$35064,3,FALSE)) -> UN | V30: =IF(B30="","",VLOOKUP(B30,'MÃO OBRA'!A$2:F$21664,6,FALSE)) -> 47.86 | W30: 3 | X30: =IFERROR(VLOOKUP(B30,'MÃO OBRA'!A:H,8,FALSE),"") -> x | Y30: =IFERROR(VLOOKUP(B30,'MÃO OBRA'!A:I,9,FALSE),"") -> 0 | Z30: =W30 -> 3 | AA30: =IF(B30="","",(V30*Z30)) -> 143.58
A31: =A30+1 -> 5 | B31: 6501 | C31: =IF(B31="","",VLOOKUP(B31,'MÃO OBRA'!A$2:G$436,2,FALSE)) -> SUBST ELO FUSIVEL LM | U31: =IF(B31="","",VLOOKUP(B31,'MÃO OBRA'!A$2:F$35064,3,FALSE)) -> 0 | V31: =IF(B31="","",VLOOKUP(B31,'MÃO OBRA'!A$2:F$21664,6,FALSE)) -> 47.86 | W31: 3 | X31: =IFERROR(VLOOKUP(B31,'MÃO OBRA'!A:H,8,FALSE),"") -> 0 | Y31: =IFERROR(VLOOKUP(B31,'MÃO OBRA'!A:I,9,FALSE),"") -> 0 | Z31: =W31 -> 3 | AA31: =IF(B31="","",(V31*Z31)) -> 143.58
A32: 6 | B32: 6082 | C32: =IF(B32="","",VLOOKUP(B32,'MÃO OBRA'!A$2:G$436,2,FALSE)) -> INST PARA-RAIOS RD < 34,5 KV LM | U32: =IF(B32="","",VLOOKUP(B32,'MÃO OBRA'!A$2:F$35064,3,FALSE)) -> UN | V32: =IF(B32="","",VLOOKUP(B32,'MÃO OBRA'!A$2:F$21664,6,FALSE)) -> 95.72 | W32: 3 | X32: =IFERROR(VLOOKUP(B32,'MÃO OBRA'!A:H,8,FALSE),"") -> x | Y32: =IFERROR(VLOOKUP(B32,'MÃO OBRA'!A:I,9,FALSE),"") -> 0 | Z32: =W32 -> 3 | AA32: =IF(B32="","",(V32*Z32)) -> 287.16
A33: =A32+1 -> 7 | B33: 6083 | C33: =IF(B33="","",VLOOKUP(B33,'MÃO OBRA'!A$2:G$436,2,FALSE)) -> INST PARA-RAIOS RD => 34,5 KV LM | U33: =IF(B33="","",VLOOKUP(B33,'MÃO OBRA'!A$2:F$35064,3,FALSE)) -> UN | V33: =IF(B33="","",VLOOKUP(B33,'MÃO OBRA'!A$2:F$21664,6,FALSE)) -> 95.72 | W33: 3 | X33: =IFERROR(VLOOKUP(B33,'MÃO OBRA'!A:H,8,FALSE),"") -> x | Y33: =IFERROR(VLOOKUP(B33,'MÃO OBRA'!A:I,9,FALSE),"") -> 0 | Z33: =W33 -> 3 | AA33: =IF(B33="","",(V33*Z33)) -> 287.16
A34: =A33+1 -> 8 | B34: 6235 | C34: =IF(B34="","",VLOOKUP(B34,'MÃO OBRA'!A$2:G$436,2,FALSE)) -> INST CONEC RD SEC LM | U34: =IF(B34="","",VLOOKUP(B34,'MÃO OBRA'!A$2:F$35064,3,FALSE)) -> UN | V34: =IF(B34="","",VLOOKUP(B34,'MÃO OBRA'!A$2:F$21664,6,FALSE)) -> 9.58 | W34: 8 | X34: =IFERROR(VLOOKUP(B34,'MÃO OBRA'!A:H,8,FALSE),"") -> x | Y34: =IFERROR(VLOOKUP(B34,'MÃO OBRA'!A:I,9,FALSE),"") -> 0 | Z34: =W34 -> 8 | AA34: =IF(B34="","",(V34*Z34)) -> 76.64
A35: =A34+1 -> 9 | B35: 6055 | C35: =IF(B35="","",VLOOKUP(B35,'MÃO OBRA'!A$2:G$436,2,FALSE)) -> DESAT PARA-RAIOS RD < 34,5 KV LM | U35: =IF(B35="","",VLOOKUP(B35,'MÃO OBRA'!A$2:F$35064,3,FALSE)) -> 0 | V35: =IF(B35="","",VLOOKUP(B35,'MÃO OBRA'!A$2:F$21664,6,FALSE)) -> 28.72 | W35: 3 | X35: =IFERROR(VLOOKUP(B35,'MÃO OBRA'!A:H,8,FALSE),"") -> 0 | Y35: =IFERROR(VLOOKUP(B35,'MÃO OBRA'!A:I,9,FALSE),"") -> 0 | Z35: =W35 -> 3 | AA35: =IF(B35="","",(V35*Z35)) -> 86.16
A36: =A35+1 -> 10 | B36: 7640 | C36: =IF(B36="","",VLOOKUP(B36,'MÃO OBRA'!A$2:G$436,2,FALSE)) -> #N/A | U36: =IF(B36="","",VLOOKUP(B36,'MÃO OBRA'!A$2:F$35064,3,FALSE)) -> 0 | V36: =IF(B36="","",VLOOKUP(B36,'MÃO OBRA'!A$2:F$21664,6,FALSE)) -> 19.14 | W36: 8 | X36: =IFERROR(VLOOKUP(B36,'MÃO OBRA'!A:H,8,FALSE),"") -> 0 | Y36: =IFERROR(VLOOKUP(B36,'MÃO OBRA'!A:I,9,FALSE),"") -> 0 | Z36: =W36 -> 8 | AA36: =IF(B36="","",(V36*Z36)) -> 153.12
A37: =A36+1 -> 11 | C37: =IF(B37="","",VLOOKUP(B37,'MÃO OBRA'!A$2:G$436,2,FALSE)) | U37: =IF(B37="","",VLOOKUP(B37,'MÃO OBRA'!A$2:F$35064,3,FALSE)) | V37: =IF(B37="","",VLOOKUP(B37,'MÃO OBRA'!A$2:F$21664,6,FALSE)) | X37: =IFERROR(VLOOKUP(B37,'MÃO OBRA'!A:H,8,FALSE),"") | Y37: =IFERROR(VLOOKUP(B37,'MÃO OBRA'!A:I,9,FALSE),"") | Z37: =W37 -> 0 | AA37: =IF(B37="","",(V37*Z37))
A38: =A37+1 -> 12 | C38: =IF(B38="","",VLOOKUP(B38,'MÃO OBRA'!A$2:G$436,2,FALSE)) | U38: =IF(B38="","",VLOOKUP(B38,'MÃO OBRA'!A$2:F$35064,3,FALSE)) | V38: =IF(B38="","",VLOOKUP(B38,'MÃO OBRA'!A$2:F$21664,6,FALSE)) | X38: =IFERROR(VLOOKUP(B38,'MÃO OBRA'!A:H,8,FALSE),"") | Y38: =IFERROR(VLOOKUP(B38,'MÃO OBRA'!A:I,9,FALSE),"") | Z38: =W38 -> 0 | AA38: =IF(B38="","",(V38*Z38))
A39: =A38+1 -> 13 | C39: =IF(B39="","",VLOOKUP(B39,'MÃO OBRA'!A$2:G$436,2,FALSE)) | U39: =IF(B39="","",VLOOKUP(B39,'MÃO OBRA'!A$2:F$35064,3,FALSE)) | V39: =IF(B39="","",VLOOKUP(B39,'MÃO OBRA'!A$2:F$21664,6,FALSE)) | X39: =IFERROR(VLOOKUP(B39,'MÃO OBRA'!A:H,8,FALSE),"") | Y39: =IFERROR(VLOOKUP(B39,'MÃO OBRA'!A:I,9,FALSE),"") | Z39: =W39 -> 0 | AA39: =IF(B39="","",(V39*Z39))
A40: =A39+1 -> 14 | C40: =IF(B40="","",VLOOKUP(B40,'MÃO OBRA'!A$2:G$436,2,FALSE)) | V40: =IF(B40="","",VLOOKUP(B40,'MÃO OBRA'!A$2:F$21664,6,FALSE)) | X40: =IFERROR(VLOOKUP(B40,'MÃO OBRA'!A:H,8,FALSE),"") | Y40: =IFERROR(VLOOKUP(B40,'MÃO OBRA'!A:I,9,FALSE),"") | Z40: =W40 -> 0 | AA40: =IF(B40="","",(V40*Z40))
A41: =A40+1 -> 15 | C41: =IF(B41="","",VLOOKUP(B41,'MÃO OBRA'!A$2:G$436,2,FALSE)) | U41: =IF(B41="","",VLOOKUP(B41,'MÃO OBRA'!A$2:F$35064,3,FALSE)) | V41: =IF(B41="","",VLOOKUP(B41,'MÃO OBRA'!A$2:F$21664,6,FALSE)) | X41: =IFERROR(VLOOKUP(B41,'MÃO OBRA'!A:H,8,FALSE),"") | Y41: =IFERROR(VLOOKUP(B41,'MÃO OBRA'!A:I,9,FALSE),"") | Z41: =W41 -> 0 | AA41: =IF(B41="","",(V41*Z41))
A42: =A41+1 -> 16 | C42: =IF(B42="","",VLOOKUP(B42,'MÃO OBRA'!A$2:G$436,2,FALSE)) | U42: =IF(B42="","",VLOOKUP(B42,'MÃO OBRA'!A$2:F$35064,3,FALSE)) | V42: =IF(B42="","",VLOOKUP(B42,'MÃO OBRA'!A$2:F$21664,6,FALSE)) | X42: =IFERROR(VLOOKUP(B42,'MÃO OBRA'!A:H,8,FALSE),"") | Y42: =IFERROR(VLOOKUP(B42,'MÃO OBRA'!A:I,9,FALSE),"") | Z42: =W42 -> 0 | AA42: =IF(B42="","",(V42*Z42))
A43: =A42+1 -> 17 | C43: =IF(B43="","",VLOOKUP(B43,'MÃO OBRA'!A$2:G$436,2,FALSE)) | U43: =IF(B43="","",VLOOKUP(B43,'MÃO OBRA'!A$2:F$35064,3,FALSE)) | V43: =IF(B43="","",VLOOKUP(B43,'MÃO OBRA'!A$2:F$21664,6,FALSE)) | X43: =IFERROR(VLOOKUP(B43,'MÃO OBRA'!A:H,8,FALSE),"") | Y43: =IFERROR(VLOOKUP(B43,'MÃO OBRA'!A:I,9,FALSE),"") | Z43: =W43 -> 0 | AA43: =IF(B43="","",(V43*Z43))
A44: =A43+1 -> 18 | C44: =IF(B44="","",VLOOKUP(B44,'MÃO OBRA'!A$2:G$436,2,FALSE)) | U44: =IF(B44="","",VLOOKUP(B44,'MÃO OBRA'!A$2:F$35064,3,FALSE)) | V44: =IF(B44="","",VLOOKUP(B44,'MÃO OBRA'!A$2:F$21664,6,FALSE)) | X44: =IFERROR(VLOOKUP(B44,'MÃO OBRA'!A:H,8,FALSE),"") | Y44: =IFERROR(VLOOKUP(B44,'MÃO OBRA'!A:I,9,FALSE),"") | Z44: =W44 -> 0 | AA44: =IF(B44="","",(V44*Z44))
A45: SUB-TOTAL | AA45: =SUM(AA27:AB44) -> 2641.95
A46: 26378 | C46: SERV. EMERG. MOBILIZAÇÃO/DESMOBILIZAÇÃO (1 HORA) | U46: HORA | V46: =IF(W46>0,(243.02),"") | AA46: =V46*W46 -> #VALUE!
A47: 26376 | C47: SERV. EMERG. FORA DO HORARIO COMERCIAL-ADICIONAL 30% | U47: ADIC | V47: =IF(W47>0,(AA45*0.3),"") | AA47: =V47*W47 -> #VALUE!
A48: 26377 | C48: SERV. EMERG. DOMINGO E FERIADO - ADICIONAL 50% | U48: ADIC | V48: =IF(W48>0,(AA45*0.5),"") | AA48: =V48*W48 -> #VALUE!
A49: TOTAL | AA49: =SUM(AA45:AB48) -> #VALUE!
A50: ITEM | B50: CÓD | C50: MATERIAL APLICADO | V50: UN | W50: OPERAÇÕES
Y51: =Y26 -> Ret. | Z51: TOTAL
...
